<?xml version="1.0" encoding="utf-8"?>
<!-- This URDF was automatically created by SolidWorks to urdf_export! Originally created by Stephen Brawner (brawner@gmail.com) 
     Commit Version: 1.6.0-1-g15f4949  Build Version: 1.6.7594.29634
     For more information, please see http://wiki.ros.org/sw_urdf_exporter -->
<robot
  name="urdf_export">
  <link
    name="base_link">
    <inertial>
      <origin
        xyz="0.093858 0.12633 0.21897"
        rpy="0 0 0" />
      <mass
        value="1.3642" />
      <inertia
        ixx="0.006457"
        ixy="1.2994E-06"
        ixz="2.2481E-08"
        iyy="0.010326"
        iyz="7.3921E-06"
        izz="0.0061127" />
    </inertial>
    <visual>
      <origin
        xyz="0 0 0"
        rpy="0 0 0" />
      <geometry>
        <mesh
          filename="package://urdf_export/meshes/base_link.STL" />
      </geometry>
      <material
        name="">
        <color
          rgba="0.79216 0.81961 0.93333 1" />
      </material>
    </visual>
    <collision>
      <origin
        xyz="0 0 0"
        rpy="0 0 0" />
      <geometry>
        <mesh
          filename="package://urdf_export/meshes/base_link.STL" />
      </geometry>
    </collision>
  </link>
  <link
    name="Link_1">
    <inertial>
      <origin
        xyz="0.020212 0.041371 -0.0052931"
        rpy="0 0 0" />
      <mass
        value="0.13194" />
      <inertia
        ixx="0.0001026"
        ixy="-4.4981E-05"
        ixz="1.9288E-06"
        iyy="9.8208E-05"
        iyz="1.7697E-06"
        izz="0.00014958" />
    </inertial>
    <visual>
      <origin
        xyz="0 0 0"
        rpy="0 0 0" />
      <geometry>
        <mesh
          filename="package://urdf_export/meshes/Link_1.STL" />
      </geometry>
      <material
        name="">
        <color
          rgba="0.79216 0.81961 0.93333 1" />
      </material>
    </visual>
    <collision>
      <origin
        xyz="0 0 0"
        rpy="0 0 0" />
      <geometry>
        <mesh
          filename="package://urdf_export/meshes/Link_1.STL" />
      </geometry>
    </collision>
  </link>
  <joint
    name="Joint_0"
    type="continuous">
    <origin
      xyz="0.061602 -0.21942 0.15614"
      rpy="1.5708 0 -0.069291" />
    <parent
      link="base_link" />
    <child
      link="Link_1" />
    <axis
      xyz="0 1 0" />
    <limit
      lower="0"
      upper="0"
      effort="0"
      velocity="0" />
  </joint>
  <link
    name="Link_2">
    <inertial>
      <origin
        xyz="0.049842 -0.087123 0.0145"
        rpy="0 0 0" />
      <mass
        value="0.1551" />
      <inertia
        ixx="0.00045958"
        ixy="0.00024247"
        ixz="7.4969E-06"
        iyy="0.00016514"
        iyz="-1.1711E-05"
        izz="0.00061443" />
    </inertial>
    <visual>
      <origin
        xyz="0 0 0"
        rpy="0 0 0" />
      <geometry>
        <mesh
          filename="package://urdf_export/meshes/Link_2.STL" />
      </geometry>
      <material
        name="">
        <color
          rgba="0.79216 0.81961 0.93333 1" />
      </material>
    </visual>
    <collision>
      <origin
        xyz="0 0 0"
        rpy="0 0 0" />
      <geometry>
        <mesh
          filename="package://urdf_export/meshes/Link_2.STL" />
      </geometry>
    </collision>
  </link>
  <joint
    name="Joint_1"
    type="continuous">
    <origin
      xyz="0.050169 0.074195 -0.0024231"
      rpy="-0.0021329 -0.096474 -3.0974" />
    <parent
      link="Link_1" />
    <child
      link="Link_2" />
    <axis
      xyz="0.048242 0 0.99884" />
  </joint>
  <link
    name="Link_3">
    <inertial>
      <origin
        xyz="0.056834 -0.0055759 -0.0081581"
        rpy="0 0 0" />
      <mass
        value="0.14369" />
      <inertia
        ixx="3.1173E-05"
        ixy="1.564E-05"
        ixz="1.582E-05"
        iyy="0.00020478"
        iyz="-1.3793E-06"
        izz="0.00021814" />
    </inertial>
    <visual>
      <origin
        xyz="0 0 0"
        rpy="0 0 0" />
      <geometry>
        <mesh
          filename="package://urdf_export/meshes/Link_3.STL" />
      </geometry>
      <material
        name="">
        <color
          rgba="0.79216 0.81961 0.93333 1" />
      </material>
    </visual>
    <collision>
      <origin
        xyz="0 0 0"
        rpy="0 0 0" />
      <geometry>
        <mesh
          filename="package://urdf_export/meshes/Link_3.STL" />
      </geometry>
    </collision>
  </link>
  <joint
    name="Joint_2"
    type="continuous">
    <origin
      xyz="0.098056 -0.17425 -0.0047359"
      rpy="-0.0011961 -0.096506 -3.1168" />
    <parent
      link="Link_2" />
    <child
      link="Link_3" />
    <axis
      xyz="0.048242 0 0.99884" />
  </joint>
  <link
    name="Link_4">
    <inertial>
      <origin
        xyz="0.0408607169742835 -0.00388673710064014 -0.00162798866586814"
        rpy="0 0 0" />
      <mass
        value="0.0383846470880527" />
      <inertia
        ixx="7.39531771506327E-06"
        ixy="6.29470932762514E-07"
        ixz="4.00920380495191E-07"
        iyy="1.39446878284893E-05"
        iyz="-9.33672780612939E-09"
        izz="1.89049583807687E-05" />
    </inertial>
    <visual>
      <origin
        xyz="0 0 0"
        rpy="0 0 0" />
      <geometry>
        <mesh
          filename="package://urdf_export/meshes/Link_4.STL" />
      </geometry>
      <material
        name="">
        <color
          rgba="0.792156862745098 0.819607843137255 0.933333333333333 1" />
      </material>
    </visual>
    <collision>
      <origin
        xyz="0 0 0"
        rpy="0 0 0" />
      <geometry>
        <mesh
          filename="package://urdf_export/meshes/Link_4.STL" />
      </geometry>
    </collision>
  </link>
  <joint
    name="Joint_3"
    type="continuous">
    <origin
      xyz="0.14561 -0.01387 -0.010114"
      rpy="-0.0078276 0.00074645 0.00037515" />
    <parent
      link="Link_3" />
    <child
      link="Link_4" />
    <axis
      xyz="0.99435 -0.094634 -0.048025" />
  </joint>
  <link
    name="End_effector">
    <inertial>
      <origin
        xyz="0.001529 -0.05263 0.018807"
        rpy="0 0 0" />
      <mass
        value="0.019695" />
      <inertia
        ixx="1.1324E-05"
        ixy="-6.6347E-07"
        ixz="1.0907E-07"
        iyy="1.7645E-06"
        iyz="1.0472E-06"
        izz="1.2014E-05" />
    </inertial>
    <visual>
      <origin
        xyz="0 0 0"
        rpy="0 0 0" />
      <geometry>
        <mesh
          filename="package://urdf_export/meshes/End_effector.STL" />
      </geometry>
      <material
        name="">
        <color
          rgba="0.79216 0.81961 0.93333 1" />
      </material>
    </visual>
    <collision>
      <origin
        xyz="0 0 0"
        rpy="0 0 0" />
      <geometry>
        <mesh
          filename="package://urdf_export/meshes/End_effector.STL" />
      </geometry>
    </collision>
  </link>
  <joint
    name="Joint_4"
    type="continuous">
    <origin
      xyz="0.049718 -0.0047317 -0.0024013"
      rpy="-0.0015344 -6.3808E-05 -0.031709" />
    <parent
      link="Link_4" />
    <child
      link="End_effector" />
    <axis
      xyz="0.04836 0.0012435 0.99883" />
  </joint>
</robot>
